Internal Server Error: /contact/
Traceback (most recent call last):
  File "/workspace/.pyenv_mirror/user/current/lib/python3.12/site-packages/django/core/handlers/exception.py", line 55, in inner
    response = get_response(request)
               ^^^^^^^^^^^^^^^^^^^^^
  File "/workspace/.pyenv_mirror/user/current/lib/python3.12/site-packages/django/core/handlers/base.py", line 197, in _get_response
    response = wrapped_callback(request, *callback_args, **callback_kwargs)
               ^^^^^^^^^^^^^^^^^^^^^^^^^^^^^^^^^^^^^^^^^^^^^^^^^^^^^^^^^^^^
  File "/workspace/NA-Share/core/views.py", line 27, in contact
    message = Message(
              ^^^^^^^^
  File "/workspace/.pyenv_mirror/user/current/lib/python3.12/site-packages/django/db/models/base.py", line 543, in __init__
    _setattr(self, field.name, rel_obj)
  File "/workspace/.pyenv_mirror/user/current/lib/python3.12/site-packages/django/db/models/fields/related_descriptors.py", line 284, in __set__
    raise ValueError(
ValueError: Cannot assign "<SimpleLazyObject: <django.contrib.auth.models.AnonymousUser object at 0x7f4a540d3f80>>": "Message.sender" must be a "User" instance.
"POST /contact/ HTTP/1.1" 500 145
Internal Server Error: /contact/
Traceback (most recent call last):
  File "/workspace/.pyenv_mirror/user/current/lib/python3.12/site-packages/django/core/handlers/exception.py", line 55, in inner
    response = get_response(request)
               ^^^^^^^^^^^^^^^^^^^^^
  File "/workspace/.pyenv_mirror/user/current/lib/python3.12/site-packages/django/core/handlers/base.py", line 197, in _get_response
    response = wrapped_callback(request, *callback_args, **callback_kwargs)
               ^^^^^^^^^^^^^^^^^^^^^^^^^^^^^^^^^^^^^^^^^^^^^^^^^^^^^^^^^^^^
  File "/workspace/NA-Share/core/views.py", line 30, in contact
    content=form.cleaned_data['name', 'email', 'message']
            ~~~~~~~~~~~~~~~~~^^^^^^^^^^^^^^^^^^^^^^^^^^^^
KeyError: ('name', 'email', 'message')
"POST /contact/ HTTP/1.1" 500 145
Internal Server Error: /contact/
Traceback (most recent call last):
  File "/workspace/.pyenv_mirror/user/current/lib/python3.12/site-packages/django/core/handlers/exception.py", line 55, in inner
    response = get_response(request)
               ^^^^^^^^^^^^^^^^^^^^^
  File "/workspace/.pyenv_mirror/user/current/lib/python3.12/site-packages/django/core/handlers/base.py", line 197, in _get_response
    response = wrapped_callback(request, *callback_args, **callback_kwargs)
               ^^^^^^^^^^^^^^^^^^^^^^^^^^^^^^^^^^^^^^^^^^^^^^^^^^^^^^^^^^^^
  File "/workspace/NA-Share/core/views.py", line 30, in contact
    content=form.cleaned_data['name', 'email', 'message']
            ~~~~~~~~~~~~~~~~~^^^^^^^^^^^^^^^^^^^^^^^^^^^^
KeyError: ('name', 'email', 'message')
"POST /contact/ HTTP/1.1" 500 145
Internal Server Error: /contact/
Traceback (most recent call last):
  File "/workspace/.pyenv_mirror/user/current/lib/python3.12/site-packages/django/core/handlers/exception.py", line 55, in inner
    response = get_response(request)
               ^^^^^^^^^^^^^^^^^^^^^
  File "/workspace/.pyenv_mirror/user/current/lib/python3.12/site-packages/django/core/handlers/base.py", line 197, in _get_response
    response = wrapped_callback(request, *callback_args, **callback_kwargs)
               ^^^^^^^^^^^^^^^^^^^^^^^^^^^^^^^^^^^^^^^^^^^^^^^^^^^^^^^^^^^^
  File "/workspace/NA-Share/core/views.py", line 30, in contact
    content=form.cleaned_data['name', 'email', 'message']
            ~~~~~~~~~~~~~~~~~^^^^^^^^^^^^^^^^^^^^^^^^^^^^
KeyError: ('name', 'email', 'message')
"POST /contact/ HTTP/1.1" 500 84100
Internal Server Error: /contact/
Traceback (most recent call last):
  File "/workspace/.pyenv_mirror/user/current/lib/python3.12/site-packages/django/core/handlers/exception.py", line 55, in inner
    response = get_response(request)
               ^^^^^^^^^^^^^^^^^^^^^
  File "/workspace/.pyenv_mirror/user/current/lib/python3.12/site-packages/django/core/handlers/base.py", line 197, in _get_response
    response = wrapped_callback(request, *callback_args, **callback_kwargs)
               ^^^^^^^^^^^^^^^^^^^^^^^^^^^^^^^^^^^^^^^^^^^^^^^^^^^^^^^^^^^^
  File "/workspace/NA-Share/core/views.py", line 27, in contact
    message = Message(
              ^^^^^^^^
  File "/workspace/.pyenv_mirror/user/current/lib/python3.12/site-packages/django/db/models/base.py", line 543, in __init__
    _setattr(self, field.name, rel_obj)
  File "/workspace/.pyenv_mirror/user/current/lib/python3.12/site-packages/django/db/models/fields/related_descriptors.py", line 284, in __set__
    raise ValueError(
ValueError: Cannot assign "<SimpleLazyObject: <django.contrib.auth.models.AnonymousUser object at 0x7fc5fbd563c0>>": "Message.sender" must be a "User" instance.
"POST /contact/ HTTP/1.1" 500 95162
Internal Server Error: /contact/
Traceback (most recent call last):
  File "/workspace/.pyenv_mirror/user/current/lib/python3.12/site-packages/django/db/backends/utils.py", line 105, in _execute
    return self.cursor.execute(sql, params)
           ^^^^^^^^^^^^^^^^^^^^^^^^^^^^^^^^
psycopg2.errors.NotNullViolation: null value in column "sender_id" of relation "core_message" violates not-null constraint
DETAIL:  Failing row contains (2, try again, 2024-08-05 12:50:46.38041+00, f, 2, null).


The above exception was the direct cause of the following exception:

Traceback (most recent call last):
  File "/workspace/.pyenv_mirror/user/current/lib/python3.12/site-packages/django/core/handlers/exception.py", line 55, in inner
    response = get_response(request)
               ^^^^^^^^^^^^^^^^^^^^^
  File "/workspace/.pyenv_mirror/user/current/lib/python3.12/site-packages/django/core/handlers/base.py", line 197, in _get_response
    response = wrapped_callback(request, *callback_args, **callback_kwargs)
               ^^^^^^^^^^^^^^^^^^^^^^^^^^^^^^^^^^^^^^^^^^^^^^^^^^^^^^^^^^^^
  File "/workspace/NA-Share/core/views.py", line 32, in contact
    message.save()
  File "/workspace/.pyenv_mirror/user/current/lib/python3.12/site-packages/django/db/models/base.py", line 822, in save
    self.save_base(
  File "/workspace/.pyenv_mirror/user/current/lib/python3.12/site-packages/django/db/models/base.py", line 909, in save_base
    updated = self._save_table(
              ^^^^^^^^^^^^^^^^^
  File "/workspace/.pyenv_mirror/user/current/lib/python3.12/site-packages/django/db/models/base.py", line 1071, in _save_table
    results = self._do_insert(
              ^^^^^^^^^^^^^^^^
  File "/workspace/.pyenv_mirror/user/current/lib/python3.12/site-packages/django/db/models/base.py", line 1112, in _do_insert
    return manager._insert(
           ^^^^^^^^^^^^^^^^
  File "/workspace/.pyenv_mirror/user/current/lib/python3.12/site-packages/django/db/models/manager.py", line 87, in manager_method
    return getattr(self.get_queryset(), name)(*args, **kwargs)
           ^^^^^^^^^^^^^^^^^^^^^^^^^^^^^^^^^^^^^^^^^^^^^^^^^^^
  File "/workspace/.pyenv_mirror/user/current/lib/python3.12/site-packages/django/db/models/query.py", line 1847, in _insert
    return query.get_compiler(using=using).execute_sql(returning_fields)
           ^^^^^^^^^^^^^^^^^^^^^^^^^^^^^^^^^^^^^^^^^^^^^^^^^^^^^^^^^^^^^
  File "/workspace/.pyenv_mirror/user/current/lib/python3.12/site-packages/django/db/models/sql/compiler.py", line 1823, in execute_sql
    cursor.execute(sql, params)
  File "/workspace/.pyenv_mirror/user/current/lib/python3.12/site-packages/django/db/backends/utils.py", line 122, in execute
    return super().execute(sql, params)
           ^^^^^^^^^^^^^^^^^^^^^^^^^^^^
  File "/workspace/.pyenv_mirror/user/current/lib/python3.12/site-packages/django/db/backends/utils.py", line 79, in execute
    return self._execute_with_wrappers(
           ^^^^^^^^^^^^^^^^^^^^^^^^^^^^
  File "/workspace/.pyenv_mirror/user/current/lib/python3.12/site-packages/django/db/backends/utils.py", line 92, in _execute_with_wrappers
    return executor(sql, params, many, context)
           ^^^^^^^^^^^^^^^^^^^^^^^^^^^^^^^^^^^^
  File "/workspace/.pyenv_mirror/user/current/lib/python3.12/site-packages/django/db/backends/utils.py", line 100, in _execute
    with self.db.wrap_database_errors:
  File "/workspace/.pyenv_mirror/user/current/lib/python3.12/site-packages/django/db/utils.py", line 91, in __exit__
    raise dj_exc_value.with_traceback(traceback) from exc_value
  File "/workspace/.pyenv_mirror/user/current/lib/python3.12/site-packages/django/db/backends/utils.py", line 105, in _execute
    return self.cursor.execute(sql, params)
           ^^^^^^^^^^^^^^^^^^^^^^^^^^^^^^^^
django.db.utils.IntegrityError: null value in column "sender_id" of relation "core_message" violates not-null constraint
DETAIL:  Failing row contains (2, try again, 2024-08-05 12:50:46.38041+00, f, 2, null).

"POST /contact/ HTTP/1.1" 500 158662
